<?xml version="1.0"?>
<robot name="ros_bot">

 <material name="white">
        <color rgba="1 1 1 1"/>   
   </material> 

   <material name="orange">
        <color rgba="1 0.3 0.1 1"/>   
   </material> 

    <material name="blue">
        <color rgba="0.2 0.2 1 1"/>   
   </material> 

   <material name="black">
        <color rgba="0 0 0 1"/>   
   </material> 
  
   <!-- BASE LINK -->

   <link name="base_link">
   
   </link>

   <!-- CHASSIS LINK -->

   <joint name="chassis_joint" type="fixed">
       <parent link="base_link"/>
       <child link="chassis"/>
       <origin xyz="0 0 0.15" />
   </joint>

   <link name="chassis">
      <visual>
          <geometry>
                <cylinder radius="0.3" length="0.3"/>
                <material name="orange"/>
          </geometry>
      </visual>
      <collision>
          <geometry>
                <cylinder radius="0.3" length="0.3"/>
          </geometry>
      </collision>
      <inertial>
          <mass value="0.3"/>
          <origin xyz="0.0 0.0 0.0" rpy="0.0 0.0 0.0" />
          <inertia ixx="0.005" ixy="0.0" ixz="0.0" iyy="0.005" iyz="0.0" izz="0.01"/>
      </inertial>

   </link>

   <!-- LEFT WHEEL LINK -->

   <joint name="left_wheel_joint" type="continuous">
        <parent link="base_link"/>
        <child link="left_wheel"/>
        <origin xyz="0 0.25 0.02" rpy="-${pi/2} 0 0"/>
        <axis xyz="0 0 1"/>
   </joint>

   <link name="left_wheel">
      <visual>
         <geometry>
             <cylinder radius="0.09" length="0.04"/>
        </geometry>
        <material name="blue"/>
      </visual>
      <collision>
         <geometry>
             <cylinder radius="0.09" length="0.04"/>
        </geometry>
      </collision>
      <inertial>
          <mass value="0.1"/>
          <origin xyz="0.0 0.0 0.0" rpy="0.0 0.0 0.0" />
          <inertia ixx="0.001" ixy="0.0" ixz="0.0" iyy="0.001" iyz="0.0" izz="0.001"/>
      </inertial>

   </link>

   <!-- RIGHT WHEEL LINK -->

   <joint name="right_wheel_joint" type="continuous">
        <parent link="base_link"/>
        <child link="right_wheel"/>
        <origin xyz="0 -0.25 0.02" rpy="${pi/2} 0 0"/>
        <axis xyz="0 0 -1"/>
   </joint>

   <link name="right_wheel">
      <visual>
         <geometry>
             <cylinder radius="0.09" length="0.04"/>
        </geometry>
        <material name="blue"/>
      </visual>
      <collision>
         <geometry>
             <cylinder radius="0.09" length="0.04"/>
        </geometry>
      </collision>
     <inertial>
          <mass value="0.1"/>
          <origin xyz="0.0 0.0 0.0" rpy="0.0 0.0 0.0" />
          <inertia ixx="0.001" ixy="0.0" ixz="0.0" iyy="0.001" iyz="0.0" izz="0.001"/>
      </inertial>

   </link>

   <!-- CASTER FRONT WHEEL -->

   <joint name="caster_front_joint" type="fixed">
       <parent link="chassis"/>
       <child link="caster_front_wheel"/>
       <origin xyz="0.24 0.0 -0.15"/>
   </joint>

   <link name="caster_front_wheel">
       <visual>
          <geometry>
              <sphere radius="0.05"/>   
          </geometry>
          <material name="black"/>
       </visual>
       <collision>
          <geometry>
              <sphere radius="0.05"/>   
          </geometry>
       </collision>
       <inertial>
          <mass value="0.1"/>
          <origin xyz="0.0 0.0 0.0" rpy="0.0 0.0 0.0" />
          <inertia ixx="0.001" ixy="0.0" ixz="0.0" iyy="0.001" iyz="0.0" izz="0.001"/>
       </inertial>
   </link>

   <!-- CASTER REAR WHEEL -->

   <joint name="caster_rear_joint" type="fixed">
       <parent link="chassis"/>
       <child link="caster_rear_wheel"/>
       <origin xyz="-0.24 0.0 -0.15"/>
   </joint>

   <link name="caster_rear_wheel">
       <visual>
          <geometry>
              <sphere radius="0.05"/>   
          </geometry>
          <material name="black"/>
       </visual>
       <collision>
          <geometry>
              <sphere radius="0.05"/>   
          </geometry>
       </collision>
       <inertial>
          <mass value="0.1"/>
          <origin xyz="0.0 0.0 0.0" rpy="0.0 0.0 0.0" />
          <inertia ixx="0.001" ixy="0.0" ixz="0.0" iyy="0.001" iyz="0.0" izz="0.001"/>
       </inertial>
   </link>

 
</robot>